<?xml version="1.0"?>
<robot name="simple_humanoid">

  <!-- Base Link -->
  <link name="base_link">
    <visual>
      <geometry><box size="0.2 0.3 0.1" /></geometry>
      <material name="blue">
        <color rgba="0 0 1 1" />
      </material>
    </visual>
    <collision>
      <geometry><box size="0.2 0.3 0.1" /></geometry>
    </collision>
    <inertial>
      <mass value="5.0" />
      <inertia ixx="0.1" ixy="0.0" ixz="0.0" iyy="0.1" iyz="0.0" izz="0.1" />
    </inertial>
  </link>

  <!-- Torso Link -->
  <link name="torso_link">
    <visual>
      <geometry><box size="0.2 0.15 0.3" /></geometry>
      <material name="grey">
        <color rgba="0.7 0.7 0.7 1" />
      </material>
    </visual>
    <collision>
      <geometry><box size="0.2 0.15 0.3" /></geometry>
    </collision>
    <inertial>
      <mass value="10.0" />
      <inertia ixx="0.5" ixy="0.0" ixz="0.0" iyy="0.5" iyz="0.0" izz="0.5" />
    </inertial>
  </link>

  <!-- Base to Torso Joint -->
  <joint name="base_to_torso_joint" type="fixed">
    <parent link="base_link" />
    <child link="torso_link" />
    <origin xyz="0 0 0.2" rpy="0 0 0" />
  </joint>

  <!-- Head Link -->
  <link name="head_link">
    <visual>
      <geometry><sphere radius="0.1" /></geometry>
      <material name="white">
        <color rgba="1 1 1 1" />
      </material>
    </visual>
    <collision>
      <geometry><sphere radius="0.1" /></geometry>
    </collision>
    <inertial>
      <mass value="2.0" />
      <inertia ixx="0.05" ixy="0.0" ixz="0.0" iyy="0.05" iyz="0.0" izz="0.05" />
    </inertial>
  </link>

  <!-- Torso to Head Joint -->
  <joint name="torso_to_head_joint" type="revolute">
    <parent link="torso_link" />
    <child link="head_link" />
    <origin xyz="0 0 0.2" rpy="0 0 0" />
    <axis xyz="0 0 1" />
    <limit lower="-1.57" upper="1.57" effort="10" velocity="1.0" />
  </joint>

  <!-- Right Arm Link -->
  <link name="right_arm_link">
    <visual>
      <geometry><cylinder radius="0.03" length="0.2" /></geometry>
      <material name="red">
        <color rgba="1 0 0 1" />
      </material>
    </visual>
    <collision>
      <geometry><cylinder radius="0.03" length="0.2" /></geometry>
    </collision>
    <inertial>
      <mass value="1.0" />
      <inertia ixx="0.01" ixy="0.0" ixz="0.0" iyy="0.01" iyz="0.0" izz="0.01" />
    </inertial>
  </link>

  <!-- Torso to Right Arm Joint -->
  <joint name="torso_to_right_arm_joint" type="revolute">
    <parent link="torso_link" />
    <child link="right_arm_link" />
    <origin xyz="-0.12 0 0.1" rpy="0 0 0" />
    <axis xyz="0 1 0" />
    <limit lower="-1.57" upper="1.57" effort="10" velocity="1.0" />
  </joint>

  <!-- Left Arm Link -->
  <link name="left_arm_link">
    <visual>
      <geometry><cylinder radius="0.03" length="0.2" /></geometry>
      <material name="green">
        <color rgba="0 1 0 1" />
      </material>
    </visual>
    <collision>
      <geometry><cylinder radius="0.03" length="0.2" /></geometry>
    </collision>
    <inertial>
      <mass value="1.0" />
      <inertia ixx="0.01" ixy="0.0" ixz="0.0" iyy="0.01" iyz="0.0" izz="0.01" />
    </inertial>
  </link>

  <!-- Torso to Left Arm Joint -->
  <joint name="torso_to_left_arm_joint" type="revolute">
    <parent link="torso_link" />
    <child link="left_arm_link" />
    <origin xyz="0.12 0 0.1" rpy="0 0 0" />
    <axis xyz="0 1 0" />
    <limit lower="-1.57" upper="1.57" effort="10" velocity="1.0" />
  </joint>

</robot>